<?xml version="1.0" ?>
<sdf version="1.8">
    <world name="car_world">
        <physics name="1ms" type="ignored">
            <max_step_size>0.001</max_step_size>
            <real_time_factor>1.0</real_time_factor>
        </physics>
        <plugin
            filename="libignition-gazebo-physics-system.so"
            name="ignition::gazebo::systems::Physics">
        </plugin>
        <plugin
            filename="libignition-gazebo-user-commands-system.so"
            name="ignition::gazebo::systems::UserCommands">
        </plugin>
        <plugin
            filename="libignition-gazebo-scene-broadcaster-system.so"
            name="ignition::gazebo::systems::SceneBroadcaster">
        </plugin>
        <plugin
            filename="libignition-gazebo-imu-system.so"
            name="ignition::gazebo::systems::Imu">
        </plugin>
        <plugin
            filename="libignition-gazebo-contact-system.so"
            name="ignition::gazebo::systems::Contact">    
        </plugin>
        <plugin
            filename="libignition-gazebo-sensors-system.so"
            name="ignition::gazebo::systems::Sensors">
            <render_engine>ogre2</render_engine>
        </plugin>

        <light type="directional" name="sun">
            <cast_shadows>true</cast_shadows>
            <pose>0 0 10 0 0 0</pose>
            <diffuse>0.8 0.8 0.8 1</diffuse>
            <specular>0.2 0.2 0.2 1</specular>
            <attenuation>
                <range>1000</range>
                <constant>0.9</constant>
                <linear>0.01</linear>
                <quadratic>0.001</quadratic>
            </attenuation>
            <direction>-0.5 0.1 -0.9</direction>
        </light>

        <model name="ground_plane">
            <static>true</static>
            <link name="link">
                <collision name="collision">
                    <geometry>
                        <plane>
                            <normal>0 0 1</normal>
                        </plane>
                    </geometry>
                </collision>
                <visual name="visual">
                    <geometry>
                        <plane>
                            <normal>0 0 1</normal>
                            <size>100 100</size>
                        </plane>
                    </geometry>
                    <material>
                        <ambient>0.8 0.8 0.8 1</ambient>
                        <diffuse>0.8 0.8 0.8 1</diffuse>
                        <specular>0.8 0.8 0.8 1</specular>
                    </material>
                </visual>
            </link>
        </model>

        <model name="vehicle_blue" canonical_link="chassis">
            <pose relative_to="world">0 0 0 0 0 0</pose>

            <frame name="lidar_frame" attached_to="chassis">
                <pose>0 0 0.5 0 0 0</pose>
            </frame>

            <link name="chassis">
                <pose relative_to="__model__">0 0 0.4 0 0 1.57</pose>
                <inertial>
                    <mass>1.14395</mass>
                    <inertia>
                        <ixx>0.095329</ixx>
                        <ixy>0</ixy>
                        <ixz>0</ixz>
                        <iyy>0.381317</iyy>
                        <iyz>0</iyz>
                        <izz>0.476646</izz>
                    </inertia>
                </inertial>
                <visual name="visual">
                    <geometry>
                        <box>
                            <size>2.0 1.0 0.5</size>
                        </box>
                    </geometry>
                    <material>
                        <ambient>0.0 0.0 1.0 1</ambient>
                        <diffuse>0.0 0.0 1.0 1</diffuse>
                        <specular>0.0 0.0 1.0 1</specular>
                    </material>
                </visual>
                <collision name="collision">
                    <geometry>
                        <box>
                            <size>2.0 1.0 0.5</size>
                        </box>
                    </geometry>
                </collision>
                <sensor name="imu_sensor" type="imu">
                    <always_on>1</always_on>
                    <update_rate>1</update_rate>
                    <visualize>true</visualize>
                    <topic>imu</topic>
                </sensor>
                 <sensor name="gpu_lidar" type="gpu_lidar">
                    <pose relative_to="lidar_frame">0 0 0 0 0 0</pose>
                    <topic>/scan/simulation</topic>
                    <update_rate>1</update_rate>
                    <ray>
                        <scan>
                            <horizontal>
                                <samples>640</samples>
                                <resolution>1</resolution>
                                <min_angle>-360</min_angle>
                                <max_angle>360</max_angle>
                            </horizontal>
                            <vertical>
                                <samples>1</samples>
                                <resolution>0.01</resolution>
                                <min_angle>0</min_angle>
                                <max_angle>1.5708</max_angle>
                            </vertical>
                        </scan>
                        <range>
                            <min>0.08</min>
                            <max>10.0</max>
                            <resolution>0.01</resolution>
                        </range>
                    </ray>
                </sensor>
                
             
            </link>
            

            <link name="right_front_wheel">
                <pose relative_to="chassis">0.5 0.6 0 -1.5707 0 0</pose>
                <visual name="visual">
                    <geometry>
                        <cylinder>
                            <radius>0.4</radius>
                            <length>0.2</length>
                        </cylinder>
                    </geometry>
                    <material>
                        <ambient>1.0 0.0 0.0 1</ambient>
                        <diffuse>1.0 0.0 0.0 1</diffuse>
                        <specular>1.0 0.0 0.0 1</specular>
                    </material>
                </visual>
                <collision name="collision">
                    <geometry>
                        <cylinder>
                            <radius>0.4</radius>
                            <length>0.2</length>
                        </cylinder>
                    </geometry>
                </collision>
            </link>

            <link name="left_front_wheel">
                <pose relative_to="chassis">-0.5 0.6 0 -1.5707 0 0</pose>
                <inertial>
                    <mass>1</mass>
                    <inertia>
                        <ixx>0.043333</ixx>
                        <ixy>0</ixy>
                        <ixz>0</ixz>
                        <iyy>0.043333</iyy>
                        <iyz>0</iyz>
                        <izz>0.08</izz>
                    </inertia>
                </inertial>
                <visual name="visual">
                    <geometry>
                        <cylinder>
                            <radius>0.4</radius>
                            <length>0.2</length>
                        </cylinder>
                    </geometry>
                    <material>
                        <ambient>1.0 0.0 0.0 1</ambient>
                        <diffuse>1.0 0.0 0.0 1</diffuse>
                        <specular>1.0 0.0 0.0 1</specular>
                    </material>
                </visual>
                <collision name="collision">
                    <geometry>
                        <cylinder>
                            <radius>0.4</radius>
                            <length>0.2</length>
                        </cylinder>
                    </geometry>
                </collision>
            </link>

            <link name="left_back_wheel">
                <pose relative_to="chassis">-0.5 -0.6 0 -1.5707 0 0</pose>
                <inertial>
                    <mass>1</mass>
                    <inertia>
                        <ixx>0.043333</ixx>
                        <ixy>0</ixy>
                        <ixz>0</ixz>
                        <iyy>0.043333</iyy>
                        <iyz>0</iyz>
                        <izz>0.08</izz>
                    </inertia>
                </inertial>
                <visual name="visual">
                    <geometry>
                        <cylinder>
                            <radius>0.4</radius>
                            <length>0.2</length>
                        </cylinder>
                    </geometry>
                    <material>
                        <ambient>1.0 0.0 0.0 1</ambient>
                        <diffuse>1.0 0.0 0.0 1</diffuse>
                        <specular>1.0 0.0 0.0 1</specular>
                    </material>
                </visual>
                <collision name="collision">
                    <geometry>
                        <cylinder>
                            <radius>0.4</radius>
                            <length>0.2</length>
                        </cylinder>
                    </geometry>
                </collision>
            </link>

            <link name="right_back_wheel">
                <pose relative_to="chassis">0.5 -0.6 0 -1.5707 0 0</pose>
                <inertial>
                    <mass>1</mass>
                    <inertia>
                        <ixx>0.043333</ixx>
                        <ixy>0</ixy>
                        <ixz>0</ixz>
                        <iyy>0.043333</iyy>
                        <iyz>0</iyz>
                        <izz>0.08</izz>
                    </inertia>
                </inertial>
                <visual name="visual">
                    <geometry>
                        <cylinder>
                            <radius>0.4</radius>
                            <length>0.2</length>
                        </cylinder>
                    </geometry>
                    <material>
                        <ambient>1.0 0.0 0.0 1</ambient>
                        <diffuse>1.0 0.0 0.0 1</diffuse>
                        <specular>1.0 0.0 0.0 1</specular>
                    </material>
                </visual>
                <collision name="collision">
                    <geometry>
                        <cylinder>
                            <radius>0.4</radius>
                            <length>0.2</length>
                        </cylinder>
                    </geometry>
                </collision>
            </link>

            <joint name="right_wheel_joint" type="revolute">
                <parent>chassis</parent>
                <child>right_front_wheel</child>
                <axis>
                    <xyz>0 0 1</xyz>
                    <limit>
                        <lower>-1.57</lower>
                        <upper>1.57</upper>
                        <effort>10</effort>
                        <velocity>5</velocity>
                    </limit>
                </axis>
            </joint>

            <joint name="left_wheel_joint" type="revolute">
                <parent>chassis</parent>
                <child>left_front_wheel</child>
                <axis>
                    <xyz>0 0 1</xyz>
                    <limit>
                        <lower>-1.57</lower>
                        <upper>1.57</upper>
                        <effort>10</effort>
                        <velocity>5</velocity>
                    </limit>
                </axis>
            </joint>

            <joint name="left_back_wheel_joint" type="revolute">
                <parent>chassis</parent>
                <child>left_back_wheel</child>
                <axis>
                    <xyz>0 0 1</xyz>
                    <limit>
                        <lower>-1.57</lower>
                        <upper>1.57</upper>
                        <effort>10</effort>
                        <velocity>5</velocity>
                    </limit>
                </axis>
            </joint>

            <joint name="right_back_wheel_joint" type="revolute">
                <parent>chassis</parent>
                <child>right_back_wheel</child>
                <axis>
                    <xyz>0 0 1</xyz>
                    <limit>
                        <lower>-1.57</lower>
                        <upper>1.57</upper>
                        <effort>10</effort>
                        <velocity>5</velocity>
                    </limit>
                </axis>
            </joint>
            <plugin
			filename="libignition-gazebo-diff-drive-system.so"
			name="ignition::gazebo::systems::DiffDrive">
			<left_joint>left_wheel_joint</left_joint>
			<right_joint>right_wheel_joint</right_joint>
			<wheel_seperation>1.2</wheel_seperation>
			<wheel_radius>0.4</wheel_radius>
			<odom_publish_frequency>1</odom_publish_frequency>
			<topic>cmd_vel</topic>
			<min_velocity>-2.0</min_velocity>
    			<max_velocity>2.0</max_velocity>
	    </plugin>
	    <plugin
			filename="libignition-gazebo-diff-drive-system.so"
			name="ignition::gazebo::systems::DiffDrive">
			<left_joint>left_back_wheel_joint</left_joint>
			<right_joint>right_back_wheel_joint</right_joint>
			<wheel_seperation>1.2</wheel_seperation>
			<wheel_radius>0.4</wheel_radius>
			<odom_publish_frequency>1</odom_publish_frequency>
			<topic>cmd_vel_back</topic>
			<min_velocity>-2.0</min_velocity>
    			<max_velocity>2.0</max_velocity>
	    </plugin>
        </model>
        <model name="Obstacle1">
	      <pose>-2 4 2.5 0 0 0</pose>
	      <link name="link">
		<collision name="collision">
		  <geometry>
		    <box>
		      <size>0.5 0.5 5.0</size>
		    </box>
		  </geometry>
		</collision>
		<visual name="visual">
		  <geometry>
		    <box>
		      <size>0.5 0.5 5.0</size>
		    </box>
		  </geometry>
		</visual>
	      </link>
    	</model>
    	<model name="Obstacle2">
	      <pose>2 4 2.5 0 0 0</pose>
	      <link name="link">
		<collision name="collision">
		  <geometry>
		    <box>
		      <size>0.5 0.5 5.0</size>
		    </box>
		  </geometry>
		</collision>
		<visual name="visual">
		  <geometry>
		    <box>
		      <size>0.5 0.5 5.0</size>
		    </box>
		  </geometry>
		</visual>
	      </link>
    	</model>
    	<model name="Obstacle3">
	      <pose>2 -4 2.5 0 0 0</pose>
	      <link name="link">
		<collision name="collision">
		  <geometry>
		    <box>
		      <size>0.5 0.5 5.0</size>
		    </box>
		  </geometry>
		</collision>
		<visual name="visual">
		  <geometry>
		    <box>
		      <size>0.5 0.5 5.0</size>
		    </box>
		  </geometry>
		</visual>
	      </link>
    	</model>
    	<model name="Obstacle4">
	      <pose>-2 -4 2.5 0 0 0</pose>
	      <link name="link">
		<collision name="collision">
		  <geometry>
		    <box>
		      <size>0.5 0.5 5.0</size>
		    </box>
		  </geometry>
		</collision>
		<visual name="visual">
		  <geometry>
		    <box>
		      <size>0.5 0.5 5.0</size>
		    </box>
		  </geometry>
		</visual>
	      </link>
    	</model>
    	
    	
    	
    		<model name="Obstacle6">
	      <pose>-4 -1 2.5 0 0 0</pose>
	      <link name="link">
		<collision name="collision">
		  <geometry>
		    <box>
		      <size>0.5 0.5 5.0</size>
		    </box>
		  </geometry>
		</collision>
		<visual name="visual">
		  <geometry>
		    <box>
		      <size>0.5 0.5 5.0</size>
		    </box>
		  </geometry>
		</visual>
	      </link>
    	</model>
    		
    		
    </world>
</sdf>

